---
layout: post
title:  使用Selenium处理浏览器选项卡
category: libraries
copyright: libraries
excerpt: Java
---

## 1. 概述

有时try/catch块会导致冗长甚至笨拙的代码结构。

在本文中，我们将重点介绍提供简洁易用的异常处理程序的[NoException 。](https://noexception.machinezoo.com/)

## 2.Maven依赖

让我们将[NoException](https://search.maven.org/classic/#search|ga|1|a%3A"noexception")添加到我们的pom.xml中：

```xml
<dependency>
    <groupId>com.machinezoo.noexception</groupId>
    <artifactId>noexception</artifactId>
    <version>1.1.0</version>
</dependency>
```

## 3.标准异常处理

让我们从一个常见的成语开始：

```java
private static Logger logger = LoggerFactory.getLogger(NoExceptionUnitTest.class);

@Test
public void whenStdExceptionHandling_thenCatchAndLog() {
    try {
        logger.info("Result is " + Integer.parseInt("foobar"));
    } catch (Throwable exception) {
        logger.error("Caught exception:", exception);
    }
}
```

我们首先分配一个Logger，然后进入一个try块。如果抛出异常，我们记录它：

```shell
09:29:28.140 [main] ERROR c.b.n.NoExceptionUnitTest 
  - Caught exception
j.l.NumberFormatException: For input string: "foobar"
at j.l.NumberFormatException.forInputString(NumberFormatException.java:65)
at j.l.Integer.parseInt(Integer.java:580)
...
```

## 4. 用NoException处理异常

### 4.1. 默认日志记录处理程序

让我们用NoException的标准异常处理程序替换它：

```java
@Test
public void whenDefaultNoException_thenCatchAndLog() {
    Exceptions 
      .log()
      .run(() -> System.out.println("Result is " + Integer.parseInt("foobar")));
}
```

此代码为我们提供了与上面几乎相同的输出：

```shell
09:36:04.461 [main] ERROR c.m.n.Exceptions 
  - Caught exception
j.l.NumberFormatException: For input string: "foobar"
at j.l.NumberFormatException.forInputString(NumberFormatException.java:65)
at j.l.Integer.parseInt(Integer.java:580)
...
```

在最基本的形式中，NoException为我们提供了一种用一行代码替换try/catch / exceptions 的方法。它执行我们传递给run()的 lambda，如果抛出异常，它会被记录下来。

### 4.2. 添加自定义记录器

如果我们仔细观察输出，我们会发现异常被记录为日志记录类，而不是我们的。

我们可以通过提供我们的记录器来解决这个问题：

```java
@Test
public void whenDefaultNoException_thenCatchAndLogWithClassName() {
    Exceptions
      .log(logger)
      .run(() -> System.out.println("Result is " + Integer.parseInt("foobar")));
}
```

这给了我们这个输出：

```shell
09:55:23.724 [main] ERROR c.b.n.NoExceptionUnitTest 
  - Caught exception
j.l.NumberFormatException: For input string: "foobar"
at j.l.NumberFormatException.forInputString(NumberFormatException.java:65)
at j.l.Integer.parseInt(Integer.java:580)
...
```

### 4.3. 提供自定义日志消息

我们可能希望使用不同于默认“Caught Exception”的消息。我们可以通过传递一个Logger作为第一个参数和一个String消息作为第二个参数来做到这一点：

```java
@Test
public void whenDefaultNoException_thenCatchAndLogWithMessage() {
    Exceptions
      .log(logger, "Something went wrong:")
      .run(() -> System.out.println("Result is " + Integer.parseInt("foobar")));
}
```

这给了我们这个输出：

```shell
09:55:23.724 [main] ERROR c.b.n.NoExceptionUnitTest 
  - Something went wrong:
j.l.NumberFormatException: For input string: "foobar"
at j.l.NumberFormatException.forInputString(NumberFormatException.java:65)
at j.l.Integer.parseInt(Integer.java:580)
...
```

但是如果我们想要做的不仅仅是记录异常怎么办，比如在parseInt()失败时插入一个回退值？

### 4.4. 指定默认值

异常可以返回包裹在Optional中的结果。让我们四处移动，以便我们可以在目标失败时使用它来提供默认值：

```java
@Test
public void
  givenDefaultValue_whenDefaultNoException_thenCatchAndLogPrintDefault() {
    System.out.println("Result is " + Exceptions
      .log(logger, "Something went wrong:")
      .get(() -> Integer.parseInt("foobar"))
      .orElse(-1));
}
```

我们仍然看到我们的异常：

```shell
12:02:26.388 [main] ERROR c.b.n.NoExceptionUnitTest
  - Caught exception java.lang.NumberFormatException: For input string: "foobar"
at j.l.NumberFormatException.forInputString(NumberFormatException.java:65)
at j.l.Integer.parseInt(Integer.java:580)
...
```

但我们也看到我们的消息也打印到控制台：

```shell
Result is -1
```

## 5. 创建自定义日志处理程序

到目前为止，我们有一个很好的方法来避免重复并使代码在简单的try/catch/log场景中更具可读性。如果我们想重用具有不同行为的处理程序怎么办？

让我们扩展NoException的ExceptionHandler类并根据异常类型执行以下两项操作之一：

```java
public class CustomExceptionHandler extends ExceptionHandler {

Logger logger = LoggerFactory.getLogger(CustomExceptionHandler.class);

    @Override
    public boolean handle(Throwable throwable) {
        if (throwable.getClass().isAssignableFrom(RuntimeException.class)
          || throwable.getClass().isAssignableFrom(Error.class)) {
            return false;
        } else {
            logger.error("Caught Exception", throwable);
            return true;
        }
    }
}
```

通过在我们看到Error或RuntimeException时返回false ，我们告诉ExceptionHandler重新抛出。通过为其他所有内容返回true，我们表明异常已被处理。

首先，我们将以标准异常运行它：

```java
@Test
public void givenCustomHandler_whenError_thenRethrowError() {
    CustomExceptionHandler customExceptionHandler = new CustomExceptionHandler();
    customExceptionHandler.run(() -> "foo".charAt(5));
}
```

我们将函数传递给继承自ExceptionHandler的自定义处理程序中的run()方法：

```shell
18:35:26.374 [main] ERROR c.b.n.CustomExceptionHandler 
  - Caught Exception 
j.l.StringIndexOutOfBoundsException: String index out of range: 5
at j.l.String.charAt(String.java:658)
at c.b.n.CustomExceptionHandling.throwSomething(CustomExceptionHandling.java:20)
at c.b.n.CustomExceptionHandling.lambda$main$0(CustomExceptionHandling.java:10)
at c.m.n.ExceptionHandler.run(ExceptionHandler.java:1474)
at c.b.n.CustomExceptionHandling.main(CustomExceptionHandling.java:10)

```

记录此异常。让我们尝试一个错误：

```java
@Test(expected = Error.class)
public void givenCustomHandler_whenException_thenCatchAndLog() {
    CustomExceptionHandler customExceptionHandler = new CustomExceptionHandler();
    customExceptionHandler.run(() -> throwError());
}

private static void throwError() {
    throw new Error("This is very bad.");
}
```

我们看到错误被重新抛入main()，而不是记录：

```shell
Exception in thread "main" java.lang.Error: This is very bad.
at c.b.n.CustomExceptionHandling.throwSomething(CustomExceptionHandling.java:15)
at c.b.n.CustomExceptionHandling.lambda$main$0(CustomExceptionHandling.java:8)
at c.m.n.ExceptionHandler.run(ExceptionHandler.java:1474)
t c.b.n.CustomExceptionHandling.main(CustomExceptionHandling.java:8)
```

所以我们有一个可重用的类，可以在整个项目中使用，以实现一致的异常处理。

## 六. 总结

借助NoException，我们可以使用一行代码简化逐个异常处理。

与往常一样，本教程的完整源代码可在[GitHub](https://github.com/tu-yucheng/taketoday-tutorial4j/tree/master/opensource-libraries/libraries-4)上获得。